{"timestamp": "2025-08-28T14:51:37.855148", "session_id": "reconforge_20250828_145137", "level": "LogLevel.ERROR", "category": "LogCategory.ERROR", "module": "__main__", "function": "startup", "message": "Application startup failed: 'ReconForgeLogger' object has no attribute 'set_log_level'", "data": {}, "duration_ms": null, "thread_id": "MainThread"}
{"timestamp": "2025-08-28T14:51:37.855725", "session_id": "reconforge_20250828_145137", "level": "LogLevel.ERROR", "category": "LogCategory.ERROR", "module": "__main__", "function": "startup", "message": "Startup traceback: Traceback (most recent call last):\n  File \"/home/kali/reconforge/main.py\", line 92, in startup\n    self.logger.set_log_level(level)\n    ^^^^^^^^^^^^^^^^^^^^^^^^^\nAttributeError: 'ReconForgeLogger' object has no attribute 'set_log_level'\n", "data": {}, "duration_ms": null, "thread_id": "MainThread"}
{"timestamp": "2025-08-28T14:52:19.183421", "session_id": "reconforge_20250828_145219", "level": "LogLevel.ERROR", "category": "LogCategory.ERROR", "module": "__main__", "function": "startup", "message": "Application startup failed: 'ReconForgeLogger' object has no attribute 'config_logger'", "data": {}, "duration_ms": null, "thread_id": "MainThread"}
{"timestamp": "2025-08-28T14:52:19.184210", "session_id": "reconforge_20250828_145219", "level": "LogLevel.ERROR", "category": "LogCategory.ERROR", "module": "__main__", "function": "startup", "message": "Startup traceback: Traceback (most recent call last):\n  File \"/home/kali/reconforge/main.py\", line 92, in startup\n    self.logger.set_log_level(level)\n    ~~~~~~~~~~~~~~~~~~~~~~~~~^^^^^^^\n  File \"/home/kali/reconforge/core/logger.py\", line 515, in set_log_level\n    self.scan_logger, self.database_logger, self.config_logger,\n                                            ^^^^^^^^^^^^^^^^^^\nAttributeError: 'ReconForgeLogger' object has no attribute 'config_logger'\n", "data": {}, "duration_ms": null, "thread_id": "MainThread"}
{"timestamp": "2025-08-28T14:52:38.138833", "session_id": "reconforge_20250828_145238", "level": "LogLevel.ERROR", "category": "LogCategory.ERROR", "module": "__main__", "function": "startup", "message": "Application startup failed: ReconForgeConfig.__init__() got an unexpected keyword argument 'config_path'. Did you mean 'config_file'?", "data": {}, "duration_ms": null, "thread_id": "MainThread"}
{"timestamp": "2025-08-28T14:52:38.139320", "session_id": "reconforge_20250828_145238", "level": "LogLevel.ERROR", "category": "LogCategory.ERROR", "module": "__main__", "function": "startup", "message": "Startup traceback: Traceback (most recent call last):\n  File \"/home/kali/reconforge/main.py\", line 105, in startup\n    self.config = ReconForgeConfig(config_path=self.config_path)\n                  ~~~~~~~~~~~~~~~~^^^^^^^^^^^^^^^^^^^^^^^^^^^^^^\nTypeError: ReconForgeConfig.__init__() got an unexpected keyword argument 'config_path'. Did you mean 'config_file'?\n", "data": {}, "duration_ms": null, "thread_id": "MainThread"}
{"timestamp": "2025-08-28T14:52:53.875571", "session_id": "reconforge_20250828_145253", "level": "LogLevel.ERROR", "category": "LogCategory.ERROR", "module": "__main__", "function": "startup", "message": "Application startup failed: argument should be a str or an os.PathLike object where __fspath__ returns a str, not 'NoneType'", "data": {}, "duration_ms": null, "thread_id": "MainThread"}
{"timestamp": "2025-08-28T14:52:53.878434", "session_id": "reconforge_20250828_145253", "level": "LogLevel.ERROR", "category": "LogCategory.ERROR", "module": "__main__", "function": "startup", "message": "Startup traceback: Traceback (most recent call last):\n  File \"/home/kali/reconforge/main.py\", line 105, in startup\n    self.config = ReconForgeConfig(config_file=self.config_path)\n                  ~~~~~~~~~~~~~~~~^^^^^^^^^^^^^^^^^^^^^^^^^^^^^^\n  File \"/home/kali/reconforge/core/config.py\", line 132, in __init__\n    self.config_file = Path(config_file)\n                       ~~~~^^^^^^^^^^^^^\n  File \"/usr/lib/python3.13/pathlib/_local.py\", line 505, in __init__\n    super().__init__(*args)\n    ~~~~~~~~~~~~~~~~^^^^^^^\n  File \"/usr/lib/python3.13/pathlib/_local.py\", line 132, in __init__\n    raise TypeError(\n    ...<2 lines>...\n        f\"not {type(path).__name__!r}\")\nTypeError: argument should be a str or an os.PathLike object where __fspath__ returns a str, not 'NoneType'\n", "data": {}, "duration_ms": null, "thread_id": "MainThread"}
{"timestamp": "2025-08-28T14:53:05.103673", "session_id": "reconforge_20250828_145305", "level": "LogLevel.ERROR", "category": "LogCategory.ERROR", "module": "__main__", "function": "startup", "message": "Application startup failed: 'ReconForgeConfig' object has no attribute 'get_database_config'", "data": {}, "duration_ms": null, "thread_id": "MainThread"}
{"timestamp": "2025-08-28T14:53:05.103673", "session_id": "reconforge_20250828_145305", "level": "LogLevel.ERROR", "category": "LogCategory.ERROR", "module": "__main__", "function": "startup", "message": "Application startup failed: 'ReconForgeConfig' object has no attribute 'get_database_config'", "data": {}, "duration_ms": null, "thread_id": "MainThread"}
{"timestamp": "2025-08-28T14:53:05.104233", "session_id": "reconforge_20250828_145305", "level": "LogLevel.ERROR", "category": "LogCategory.ERROR", "module": "__main__", "function": "startup", "message": "Startup traceback: Traceback (most recent call last):\n  File \"/home/kali/reconforge/main.py\", line 115, in startup\n    db_config = self.config.get_database_config()\n                ^^^^^^^^^^^^^^^^^^^^^^^^^^^^^^^\nAttributeError: 'ReconForgeConfig' object has no attribute 'get_database_config'\n", "data": {}, "duration_ms": null, "thread_id": "MainThread"}
{"timestamp": "2025-08-28T14:53:05.104233", "session_id": "reconforge_20250828_145305", "level": "LogLevel.ERROR", "category": "LogCategory.ERROR", "module": "__main__", "function": "startup", "message": "Startup traceback: Traceback (most recent call last):\n  File \"/home/kali/reconforge/main.py\", line 115, in startup\n    db_config = self.config.get_database_config()\n                ^^^^^^^^^^^^^^^^^^^^^^^^^^^^^^^\nAttributeError: 'ReconForgeConfig' object has no attribute 'get_database_config'\n", "data": {}, "duration_ms": null, "thread_id": "MainThread"}
{"timestamp": "2025-08-28T14:53:29.491351", "session_id": "reconforge_20250828_145329", "level": "LogLevel.ERROR", "category": "LogCategory.ERROR", "module": "__main__", "function": "startup", "message": "Application startup failed: ReconForgeDatabase.__init__() got an unexpected keyword argument 'logger'", "data": {}, "duration_ms": null, "thread_id": "MainThread"}
{"timestamp": "2025-08-28T14:53:29.491351", "session_id": "reconforge_20250828_145329", "level": "LogLevel.ERROR", "category": "LogCategory.ERROR", "module": "__main__", "function": "startup", "message": "Application startup failed: ReconForgeDatabase.__init__() got an unexpected keyword argument 'logger'", "data": {}, "duration_ms": null, "thread_id": "MainThread"}
{"timestamp": "2025-08-28T14:53:29.491857", "session_id": "reconforge_20250828_145329", "level": "LogLevel.ERROR", "category": "LogCategory.ERROR", "module": "__main__", "function": "startup", "message": "Startup traceback: Traceback (most recent call last):\n  File \"/home/kali/reconforge/main.py\", line 115, in startup\n    self.database = ReconForgeDatabase(\n                    ~~~~~~~~~~~~~~~~~~^\n        db_path='data/reconforge.db',\n        ^^^^^^^^^^^^^^^^^^^^^^^^^^^^^\n        logger=self.logger\n        ^^^^^^^^^^^^^^^^^^\n    )\n    ^\nTypeError: ReconForgeDatabase.__init__() got an unexpected keyword argument 'logger'\n", "data": {}, "duration_ms": null, "thread_id": "MainThread"}
{"timestamp": "2025-08-28T14:53:29.491857", "session_id": "reconforge_20250828_145329", "level": "LogLevel.ERROR", "category": "LogCategory.ERROR", "module": "__main__", "function": "startup", "message": "Startup traceback: Traceback (most recent call last):\n  File \"/home/kali/reconforge/main.py\", line 115, in startup\n    self.database = ReconForgeDatabase(\n                    ~~~~~~~~~~~~~~~~~~^\n        db_path='data/reconforge.db',\n        ^^^^^^^^^^^^^^^^^^^^^^^^^^^^^\n        logger=self.logger\n        ^^^^^^^^^^^^^^^^^^\n    )\n    ^\nTypeError: ReconForgeDatabase.__init__() got an unexpected keyword argument 'logger'\n", "data": {}, "duration_ms": null, "thread_id": "MainThread"}
{"timestamp": "2025-08-28T14:53:46.938327", "session_id": "reconforge_20250828_145346", "level": "LogLevel.ERROR", "category": "LogCategory.ERROR", "module": "__main__", "function": "startup", "message": "Application startup failed: 'ReconForgeDatabase' object has no attribute 'initialize'", "data": {}, "duration_ms": null, "thread_id": "MainThread"}
{"timestamp": "2025-08-28T14:53:46.938327", "session_id": "reconforge_20250828_145346", "level": "LogLevel.ERROR", "category": "LogCategory.ERROR", "module": "__main__", "function": "startup", "message": "Application startup failed: 'ReconForgeDatabase' object has no attribute 'initialize'", "data": {}, "duration_ms": null, "thread_id": "MainThread"}
{"timestamp": "2025-08-28T14:53:46.938896", "session_id": "reconforge_20250828_145346", "level": "LogLevel.ERROR", "category": "LogCategory.ERROR", "module": "__main__", "function": "startup", "message": "Startup traceback: Traceback (most recent call last):\n  File \"/home/kali/reconforge/main.py\", line 119, in startup\n    if not self.database.initialize():\n           ^^^^^^^^^^^^^^^^^^^^^^^^\nAttributeError: 'ReconForgeDatabase' object has no attribute 'initialize'\n", "data": {}, "duration_ms": null, "thread_id": "MainThread"}
{"timestamp": "2025-08-28T14:53:46.938896", "session_id": "reconforge_20250828_145346", "level": "LogLevel.ERROR", "category": "LogCategory.ERROR", "module": "__main__", "function": "startup", "message": "Startup traceback: Traceback (most recent call last):\n  File \"/home/kali/reconforge/main.py\", line 119, in startup\n    if not self.database.initialize():\n           ^^^^^^^^^^^^^^^^^^^^^^^^\nAttributeError: 'ReconForgeDatabase' object has no attribute 'initialize'\n", "data": {}, "duration_ms": null, "thread_id": "MainThread"}
{"timestamp": "2025-08-28T14:54:05.181028", "session_id": "reconforge_20250828_145404", "level": "LogLevel.ERROR", "category": "LogCategory.ERROR", "module": "__main__", "function": "startup", "message": "Application startup failed: 'ReconForgeLogger' object has no attribute 'log_tool'", "data": {}, "duration_ms": null, "thread_id": "MainThread"}
{"timestamp": "2025-08-28T14:54:05.181028", "session_id": "reconforge_20250828_145404", "level": "LogLevel.ERROR", "category": "LogCategory.ERROR", "module": "__main__", "function": "startup", "message": "Application startup failed: 'ReconForgeLogger' object has no attribute 'log_tool'", "data": {}, "duration_ms": null, "thread_id": "MainThread"}
{"timestamp": "2025-08-28T14:54:05.181752", "session_id": "reconforge_20250828_145404", "level": "LogLevel.ERROR", "category": "LogCategory.ERROR", "module": "__main__", "function": "startup", "message": "Startup traceback: Traceback (most recent call last):\n  File \"/home/kali/reconforge/main.py\", line 143, in startup\n    self.logger.log_tool(f\"Available: {tool.name} - {tool.description}\")\n    ^^^^^^^^^^^^^^^^^^^^\nAttributeError: 'ReconForgeLogger' object has no attribute 'log_tool'\n", "data": {}, "duration_ms": null, "thread_id": "MainThread"}
{"timestamp": "2025-08-28T14:54:05.181752", "session_id": "reconforge_20250828_145404", "level": "LogLevel.ERROR", "category": "LogCategory.ERROR", "module": "__main__", "function": "startup", "message": "Startup traceback: Traceback (most recent call last):\n  File \"/home/kali/reconforge/main.py\", line 143, in startup\n    self.logger.log_tool(f\"Available: {tool.name} - {tool.description}\")\n    ^^^^^^^^^^^^^^^^^^^^\nAttributeError: 'ReconForgeLogger' object has no attribute 'log_tool'\n", "data": {}, "duration_ms": null, "thread_id": "MainThread"}
{"timestamp": "2025-08-28T14:54:23.366206", "session_id": "reconforge_20250828_145422", "level": "LogLevel.ERROR", "category": "LogCategory.ERROR", "module": "__main__", "function": "startup", "message": "Application startup failed: 'ReconForgeDatabase' object has no attribute 'start_session'", "data": {}, "duration_ms": null, "thread_id": "MainThread"}
{"timestamp": "2025-08-28T14:54:23.366206", "session_id": "reconforge_20250828_145422", "level": "LogLevel.ERROR", "category": "LogCategory.ERROR", "module": "__main__", "function": "startup", "message": "Application startup failed: 'ReconForgeDatabase' object has no attribute 'start_session'", "data": {}, "duration_ms": null, "thread_id": "MainThread"}
{"timestamp": "2025-08-28T14:54:23.366961", "session_id": "reconforge_20250828_145422", "level": "LogLevel.ERROR", "category": "LogCategory.ERROR", "module": "__main__", "function": "startup", "message": "Startup traceback: Traceback (most recent call last):\n  File \"/home/kali/reconforge/main.py\", line 157, in startup\n    if not self.database.start_session(self.session_id, session_data):\n           ^^^^^^^^^^^^^^^^^^^^^^^^^^^\nAttributeError: 'ReconForgeDatabase' object has no attribute 'start_session'. Did you mean: 'create_session'?\n", "data": {}, "duration_ms": null, "thread_id": "MainThread"}
{"timestamp": "2025-08-28T14:54:23.366961", "session_id": "reconforge_20250828_145422", "level": "LogLevel.ERROR", "category": "LogCategory.ERROR", "module": "__main__", "function": "startup", "message": "Startup traceback: Traceback (most recent call last):\n  File \"/home/kali/reconforge/main.py\", line 157, in startup\n    if not self.database.start_session(self.session_id, session_data):\n           ^^^^^^^^^^^^^^^^^^^^^^^^^^^\nAttributeError: 'ReconForgeDatabase' object has no attribute 'start_session'. Did you mean: 'create_session'?\n", "data": {}, "duration_ms": null, "thread_id": "MainThread"}
{"timestamp": "2025-08-28T14:54:40.868419", "session_id": "reconforge_20250828_145440", "level": "LogLevel.ERROR", "category": "LogCategory.ERROR", "module": "core.logger", "function": "__exit__", "message": "Operation 'core.database.end_session' failed with exception", "data": {"operation_id": "core.database.end_session_1756407280867", "exception_type": "TypeError", "exception_message": "ReconForgeDatabase.end_session() takes 2 positional arguments but 3 were given", "stack_trace": "Traceback (most recent call last):\n  File \"/home/kali/reconforge/core/logger.py\", line 591, in wrapper\n    result = func(*args, **kwargs)\nTypeError: ReconForgeDatabase.end_session() takes 2 positional arguments but 3 were given\n", "exception_args": ["ReconForgeDatabase.end_session() takes 2 positional arguments but 3 were given"]}, "duration_ms": null, "thread_id": "MainThread"}
{"timestamp": "2025-08-28T14:54:40.868419", "session_id": "reconforge_20250828_145440", "level": "LogLevel.ERROR", "category": "LogCategory.ERROR", "module": "core.logger", "function": "__exit__", "message": "Operation 'core.database.end_session' failed with exception", "data": {"operation_id": "core.database.end_session_1756407280867", "exception_type": "TypeError", "exception_message": "ReconForgeDatabase.end_session() takes 2 positional arguments but 3 were given", "stack_trace": "Traceback (most recent call last):\n  File \"/home/kali/reconforge/core/logger.py\", line 591, in wrapper\n    result = func(*args, **kwargs)\nTypeError: ReconForgeDatabase.end_session() takes 2 positional arguments but 3 were given\n", "exception_args": ["ReconForgeDatabase.end_session() takes 2 positional arguments but 3 were given"]}, "duration_ms": null, "thread_id": "MainThread"}
{"timestamp": "2025-08-28T14:54:40.868755", "session_id": "reconforge_20250828_145440", "level": "LogLevel.ERROR", "category": "LogCategory.ERROR", "module": "__main__", "function": "shutdown", "message": "Shutdown error: ReconForgeDatabase.end_session() takes 2 positional arguments but 3 were given", "data": {}, "duration_ms": null, "thread_id": "MainThread"}
{"timestamp": "2025-08-28T14:54:40.868755", "session_id": "reconforge_20250828_145440", "level": "LogLevel.ERROR", "category": "LogCategory.ERROR", "module": "__main__", "function": "shutdown", "message": "Shutdown error: ReconForgeDatabase.end_session() takes 2 positional arguments but 3 were given", "data": {}, "duration_ms": null, "thread_id": "MainThread"}
{"timestamp": "2025-08-28T14:55:13.187587", "session_id": "reconforge_20250828_145512", "level": "LogLevel.ERROR", "category": "LogCategory.ERROR", "module": "core.logger", "function": "__exit__", "message": "Operation 'core.database.end_session' failed with exception", "data": {"operation_id": "core.database.end_session_1756407313187", "exception_type": "TypeError", "exception_message": "ReconForgeDatabase.end_session() takes 2 positional arguments but 3 were given", "stack_trace": "Traceback (most recent call last):\n  File \"/home/kali/reconforge/core/logger.py\", line 591, in wrapper\n    result = func(*args, **kwargs)\nTypeError: ReconForgeDatabase.end_session() takes 2 positional arguments but 3 were given\n", "exception_args": ["ReconForgeDatabase.end_session() takes 2 positional arguments but 3 were given"]}, "duration_ms": null, "thread_id": "MainThread"}
{"timestamp": "2025-08-28T14:55:13.187587", "session_id": "reconforge_20250828_145512", "level": "LogLevel.ERROR", "category": "LogCategory.ERROR", "module": "core.logger", "function": "__exit__", "message": "Operation 'core.database.end_session' failed with exception", "data": {"operation_id": "core.database.end_session_1756407313187", "exception_type": "TypeError", "exception_message": "ReconForgeDatabase.end_session() takes 2 positional arguments but 3 were given", "stack_trace": "Traceback (most recent call last):\n  File \"/home/kali/reconforge/core/logger.py\", line 591, in wrapper\n    result = func(*args, **kwargs)\nTypeError: ReconForgeDatabase.end_session() takes 2 positional arguments but 3 were given\n", "exception_args": ["ReconForgeDatabase.end_session() takes 2 positional arguments but 3 were given"]}, "duration_ms": null, "thread_id": "MainThread"}
{"timestamp": "2025-08-28T14:55:13.187891", "session_id": "reconforge_20250828_145512", "level": "LogLevel.ERROR", "category": "LogCategory.ERROR", "module": "__main__", "function": "shutdown", "message": "Shutdown error: ReconForgeDatabase.end_session() takes 2 positional arguments but 3 were given", "data": {}, "duration_ms": null, "thread_id": "MainThread"}
{"timestamp": "2025-08-28T14:55:13.187891", "session_id": "reconforge_20250828_145512", "level": "LogLevel.ERROR", "category": "LogCategory.ERROR", "module": "__main__", "function": "shutdown", "message": "Shutdown error: ReconForgeDatabase.end_session() takes 2 positional arguments but 3 were given", "data": {}, "duration_ms": null, "thread_id": "MainThread"}
{"timestamp": "2025-08-30T12:15:29.903811", "session_id": "reconforge_20250830_121529", "level": "LogLevel.ERROR", "category": "LogCategory.ERROR", "module": "__main__", "function": "startup", "message": "Application startup failed: 'ReconForgeConfig' object has no attribute 'get_setting'", "data": {}, "duration_ms": null, "thread_id": "MainThread"}
{"timestamp": "2025-08-30T12:15:29.903811", "session_id": "reconforge_20250830_121529", "level": "LogLevel.ERROR", "category": "LogCategory.ERROR", "module": "__main__", "function": "startup", "message": "Application startup failed: 'ReconForgeConfig' object has no attribute 'get_setting'", "data": {}, "duration_ms": null, "thread_id": "MainThread"}
{"timestamp": "2025-08-30T12:15:29.904742", "session_id": "reconforge_20250830_121529", "level": "LogLevel.ERROR", "category": "LogCategory.ERROR", "module": "__main__", "function": "startup", "message": "Startup traceback: Traceback (most recent call last):\n  File \"/home/kali/reconforge/main.py\", line 165, in startup\n    self.terminal_ui = TerminalUI(\n                       ~~~~~~~~~~^\n        logger=self.logger,\n        ^^^^^^^^^^^^^^^^^^^\n    ...<2 lines>...\n        utils=self.utils\n        ^^^^^^^^^^^^^^^^\n    )\n    ^\n  File \"/home/kali/reconforge/interface/terminal_ui.py\", line 36, in __init__\n    theme_name = config.get_setting('TERMINAL', 'theme', 'default')\n                 ^^^^^^^^^^^^^^^^^^\nAttributeError: 'ReconForgeConfig' object has no attribute 'get_setting'\n", "data": {}, "duration_ms": null, "thread_id": "MainThread"}
{"timestamp": "2025-08-30T12:15:29.904742", "session_id": "reconforge_20250830_121529", "level": "LogLevel.ERROR", "category": "LogCategory.ERROR", "module": "__main__", "function": "startup", "message": "Startup traceback: Traceback (most recent call last):\n  File \"/home/kali/reconforge/main.py\", line 165, in startup\n    self.terminal_ui = TerminalUI(\n                       ~~~~~~~~~~^\n        logger=self.logger,\n        ^^^^^^^^^^^^^^^^^^^\n    ...<2 lines>...\n        utils=self.utils\n        ^^^^^^^^^^^^^^^^\n    )\n    ^\n  File \"/home/kali/reconforge/interface/terminal_ui.py\", line 36, in __init__\n    theme_name = config.get_setting('TERMINAL', 'theme', 'default')\n                 ^^^^^^^^^^^^^^^^^^\nAttributeError: 'ReconForgeConfig' object has no attribute 'get_setting'\n", "data": {}, "duration_ms": null, "thread_id": "MainThread"}
{"timestamp": "2025-08-30T12:16:03.641203", "session_id": "reconforge_20250830_121603", "level": "LogLevel.ERROR", "category": "LogCategory.ERROR", "module": "interface.terminal_ui", "function": "run", "message": "Terminal interface error: 'ReconForgeConfig' object has no attribute 'get_setting'", "data": {}, "duration_ms": null, "thread_id": "MainThread"}
{"timestamp": "2025-08-30T12:16:03.641203", "session_id": "reconforge_20250830_121603", "level": "LogLevel.ERROR", "category": "LogCategory.ERROR", "module": "interface.terminal_ui", "function": "run", "message": "Terminal interface error: 'ReconForgeConfig' object has no attribute 'get_setting'", "data": {}, "duration_ms": null, "thread_id": "MainThread"}
{"timestamp": "2025-08-30T12:16:03.642400", "session_id": "reconforge_20250830_121603", "level": "LogLevel.ERROR", "category": "LogCategory.ERROR", "module": "interface.terminal_ui", "function": "run", "message": "Terminal UI traceback: Traceback (most recent call last):\n  File \"/home/kali/reconforge/interface/terminal_ui.py\", line 76, in run\n    if self._needs_first_time_setup():\n       ~~~~~~~~~~~~~~~~~~~~~~~~~~~~^^\n  File \"/home/kali/reconforge/interface/terminal_ui.py\", line 151, in _needs_first_time_setup\n    return not self.config.get_setting('GENERAL', 'setup_completed', False)\n               ^^^^^^^^^^^^^^^^^^^^^^^\nAttributeError: 'ReconForgeConfig' object has no attribute 'get_setting'\n", "data": {}, "duration_ms": null, "thread_id": "MainThread"}
{"timestamp": "2025-08-30T12:16:03.642400", "session_id": "reconforge_20250830_121603", "level": "LogLevel.ERROR", "category": "LogCategory.ERROR", "module": "interface.terminal_ui", "function": "run", "message": "Terminal UI traceback: Traceback (most recent call last):\n  File \"/home/kali/reconforge/interface/terminal_ui.py\", line 76, in run\n    if self._needs_first_time_setup():\n       ~~~~~~~~~~~~~~~~~~~~~~~~~~~~^^\n  File \"/home/kali/reconforge/interface/terminal_ui.py\", line 151, in _needs_first_time_setup\n    return not self.config.get_setting('GENERAL', 'setup_completed', False)\n               ^^^^^^^^^^^^^^^^^^^^^^^\nAttributeError: 'ReconForgeConfig' object has no attribute 'get_setting'\n", "data": {}, "duration_ms": null, "thread_id": "MainThread"}
