2025-08-28 14:52:19 | reconforge.main      | INFO     | _log_to_appropriate_logger | [SYSTEM] ReconForge logging system initialized | Data: {"session_id": "reconforge_20250828_145219", "log_directory": "logs", "session_start": "2025-08-28T14:52:19.182787", "python_version": "3.13.6 (main, Aug  7 2025, 10:53:54) [GCC 14.2.0]", "platform": "linux"}
2025-08-28 14:52:19 | reconforge.main      | ERROR    | _log_to_appropriate_logger | [ERROR] Application startup failed: 'ReconForgeLogger' object has no attribute 'config_logger'
2025-08-28 14:52:19 | reconforge.main      | ERROR    | _log_to_appropriate_logger | [ERROR] Startup traceback: Traceback (most recent call last):
  File "/home/kali/reconforge/main.py", line 92, in startup
    self.logger.set_log_level(level)
    ~~~~~~~~~~~~~~~~~~~~~~~~~^^^^^^^
  File "/home/kali/reconforge/core/logger.py", line 515, in set_log_level
    self.scan_logger, self.database_logger, self.config_logger,
                                            ^^^^^^^^^^^^^^^^^^
AttributeError: 'ReconForgeLogger' object has no attribute 'config_logger'

