2025-08-28 14:52:38 | reconforge.main      | INFO     | _log_to_appropriate_logger | [SYSTEM] ReconForge logging system initialized | Data: {"session_id": "reconforge_20250828_145238", "log_directory": "logs", "session_start": "2025-08-28T14:52:38.137878", "python_version": "3.13.6 (main, Aug  7 2025, 10:53:54) [GCC 14.2.0]", "platform": "linux"}
2025-08-28 14:52:38 | reconforge.main      | INFO     | _log_to_appropriate_logger | [SYSTEM] Log level changed to INFO
2025-08-28 14:52:38 | reconforge.main      | INFO     | _log_to_appropriate_logger | [SYSTEM] === ReconForge Application Startup ===
2025-08-28 14:52:38 | reconforge.main      | INFO     | _log_to_appropriate_logger | [SYSTEM] Version: 2.0.0
2025-08-28 14:52:38 | reconforge.main      | INFO     | _log_to_appropriate_logger | [SYSTEM] Build Date: 2025-08-28
2025-08-28 14:52:38 | reconforge.main      | INFO     | _log_to_appropriate_logger | [SYSTEM] Startup Time: 2025-08-28T18:52:38.137808+00:00
2025-08-28 14:52:38 | reconforge.main      | INFO     | _log_to_appropriate_logger | [SYSTEM] Python Version: 3.13.6 (main, Aug  7 2025, 10:53:54) [GCC 14.2.0]
2025-08-28 14:52:38 | reconforge.main      | INFO     | _log_to_appropriate_logger | [SYSTEM] Working Directory: /home/kali/reconforge
2025-08-28 14:52:38 | reconforge.main      | ERROR    | _log_to_appropriate_logger | [ERROR] Application startup failed: ReconForgeConfig.__init__() got an unexpected keyword argument 'config_path'. Did you mean 'config_file'?
2025-08-28 14:52:38 | reconforge.main      | ERROR    | _log_to_appropriate_logger | [ERROR] Startup traceback: Traceback (most recent call last):
  File "/home/kali/reconforge/main.py", line 105, in startup
    self.config = ReconForgeConfig(config_path=self.config_path)
                  ~~~~~~~~~~~~~~~~^^^^^^^^^^^^^^^^^^^^^^^^^^^^^^
TypeError: ReconForgeConfig.__init__() got an unexpected keyword argument 'config_path'. Did you mean 'config_file'?

